<?xml version="1.0"?>
<sdf version="1.6">
    <model name="X1">
        <enable_wind>1</enable_wind>
        <static>0</static>
        <link name="base_link">
            <inertial>
                <pose frame="">0.0 0.0 0.062 0 0 0</pose>
                <mass>46.034</mass>
                <inertia>
                    <ixx>0.613201</ixx>
                    <ixy>-0.0236401</ixy>
                    <ixz>-0.1197</ixz>
                    <iyy>1.7496</iyy>
                    <iyz>-0.00154411</iyz>
                    <izz>2.0406</izz>
                </inertia>
            </inertial>
            <collision name="base_link_collision">
                <pose frame="">0 0 0.12 0 0 0</pose>
                <geometry>
                    <box>
                        <size>0.9874 0.5709 0.05</size>
                    </box>
                </geometry>
            </collision>
            <collision name="base_link_collision_bottom">
                <pose frame="">0 0 0.046 0 0 0</pose>
                <geometry>
                    <box>
                        <size>0.80 0.5709 0.095</size>
                    </box>
                </geometry>
            </collision>
            <collision name="base_link_collision_1">
                <pose frame="">0 0 0.185625 0 0 0</pose>
                <geometry>
                    <box>
                        <size>0.78992 0.5709 0.12375</size>
                    </box>
                </geometry>
            </collision>
            <collision name="top_plate_collision">
                <pose frame="">0.0812 0 0.245 0 0 0</pose>
                <geometry>
                    <mesh>
                        <uri>meshes/top_plate.dae</uri>
                    </mesh>
                </geometry>
            </collision>
            <collision name="top_plate_collision_2">
                <pose frame="">0.0812 0 0.245 0 0 0</pose>
                <geometry>
                    <box>
                        <size>0.32 0.41 0.09</size>
                    </box>
                </geometry>
            </collision>
            <visual name="base_link_visual">
                <pose frame="">0 0 0 0 0 -3.14159</pose>
                <geometry>
                    <mesh>
                        <uri>meshes/chassis.dae</uri>
                    </mesh>
                </geometry>
            </visual>
            <visual name="center_left_headlight_visual">
                <pose frame="">0.485766 0.0844 0.124431 0 0 -3.14159</pose>
                <geometry>
                    <mesh>
                        <uri>meshes/headlight.dae</uri>
                    </mesh>
                </geometry>
            </visual>
            <visual name="center_right_headlight_visual">
                <pose frame="">0.485766 -0.0844 0.124431 0 0 -3.14159</pose>
                <geometry>
                    <mesh>
                        <uri>meshes/headlight.dae</uri>
                    </mesh>
                </geometry>
            </visual>
            <visual name="left_headlight_visual">
                <pose frame="">0.461459 0.216803 0.124431 0 0 -3.14159</pose>
                <geometry>
                    <mesh>
                        <uri>meshes/headlight.dae</uri>
                    </mesh>
                </geometry>
            </visual>
            <visual name="marker_visual_1">
                <pose frame="">0.066047 0.212211 0.209188 -3.14159 1.57079 -1.60259</pose>
                <geometry>
                    <mesh>
                        <uri>meshes/led.dae</uri>
                    </mesh>
                </geometry>
            </visual>
            <visual name="marker_visual_2">
                <pose frame="">-0.066047 0.212211 0.209188 -3.14159 1.57079 -1.60259</pose>
                <geometry>
                    <mesh>
                        <uri>meshes/led.dae</uri>
                    </mesh>
                </geometry>
            </visual>
            <visual name="marker_visual_3">
                <pose frame="">-0.42493 0 0.209188 3.14159 1.57079 7e-06</pose>
                <geometry>
                    <mesh>
                        <uri>meshes/led.dae</uri>
                    </mesh>
                </geometry>
            </visual>
            <visual name="marker_visual_4">
                <pose frame="">-0.42493 0.13619 0.209188 3.14159 1.57079 7e-06</pose>
                <geometry>
                    <mesh>
                        <uri>meshes/led.dae</uri>
                    </mesh>
                </geometry>
            </visual>
            <visual name="marker_visual_5">
                <pose frame="">-0.42493 -0.13619 0.209188 3.14159 1.57079 7e-06</pose>
                <geometry>
                    <mesh>
                        <uri>meshes/led.dae</uri>
                    </mesh>
                </geometry>
            </visual>
            <visual name="right_headlight_visual">
                <pose frame="">0.461459 -0.216803 0.124431 0 0 -3.14159</pose>
                <geometry>
                    <mesh>
                        <uri>meshes/headlight.dae</uri>
                    </mesh>
                </geometry>
            </visual>
            <visual name="marker_visual_6">
                <pose frame="">0.066047 -0.212211 0.209188 3.14159 1.57079 1.60259</pose>
                <geometry>
                    <mesh>
                        <uri>meshes/led.dae</uri>
                    </mesh>
                </geometry>
            </visual>
            <visual name="marker_visual_7">
                <pose frame="">-0.066047 -0.212211 0.209188 3.14159 1.57079 1.60259</pose>
                <geometry>
                    <mesh>
                        <uri>meshes/led.dae</uri>
                    </mesh>
                </geometry>
            </visual>
            <visual name="top_plate_visual">
                <pose frame="">0.0812 0 0.245 0 0 0</pose>
                <geometry>
                    <mesh>
                        <uri>meshes/top_plate.dae</uri>
                    </mesh>
                </geometry>
            </visual>
            <light name="left_light_source" type="spot">
                <visualize>false</visualize>
                <pose frame="">0.514147 0.216803 0.180 3.14159 1.56859 0</pose>
                <attenuation>
                    <range>10</range>
                    <linear>0</linear>
                    <constant>0.1</constant>
                    <quadratic>0.0025</quadratic>
                </attenuation>
                <diffuse>0.8 0.8 0.5 1</diffuse>
                <specular>0.8 0.8 0.5 1</specular>
                <spot>
                    <inner_angle>1</inner_angle>
                    <outer_angle>1.1</outer_angle>
                    <falloff>1</falloff>
                </spot>
                <direction>0 0 -1</direction>
                <cast_shadows>1</cast_shadows>
            </light>
<!-- <light name="center_left_light" type="spot">
                <visualize>false</visualize>
                <pose frame="">0.538 0.0844 0.180 3.14159 1.56859 0</pose>
                <attenuation>
                    <range>10</range>
                    <linear>0</linear>
                    <constant>0.1</constant>
                    <quadratic>0.0025</quadratic>
                </attenuation>
                <diffuse>0.8 0.8 0.5 1</diffuse>
                <specular>0.8 0.8 0.5 1</specular>
                <spot>
                    <inner_angle>1</inner_angle>
                    <outer_angle>1.1</outer_angle>
                    <falloff>1</falloff>
                </spot>
                <direction>0 0 -1</direction>
                <cast_shadows>1</cast_shadows>
            </light>
            <light name="center_right_light" type="spot">
                <visualize>false</visualize>
                <pose frame="">0.538 -0.0844 0.180 3.14159 1.56859 0</pose>
                <attenuation>
                    <range>10</range>
                    <linear>0</linear>
                    <constant>0.1</constant>
                    <quadratic>0.0025</quadratic>
                </attenuation>
                <diffuse>0.8 0.8 0.5 1</diffuse>
                <specular>0.8 0.8 0.5 1</specular>
                <spot>
                    <inner_angle>1</inner_angle>
                    <outer_angle>1.1</outer_angle>
                    <falloff>1</falloff>
                </spot>
                <direction>0 0 -1</direction>
                <cast_shadows>1</cast_shadows>
            </light> -->
            <light name="right_light_source" type="spot">
                <pose frame="">0.514147 -0.216803 0.180 3.14159 1.56859 0</pose>
                <visualize>false</visualize>
                <attenuation>
                    <range>10</range>
                    <linear>0</linear>
                    <constant>0.1</constant>
                    <quadratic>0.0025</quadratic>
                </attenuation>
                <diffuse>0.8 0.8 0.5 1</diffuse>
                <specular>0.8 0.8 0.5 1</specular>
                <spot>
                    <inner_angle>1</inner_angle>
                    <outer_angle>1.1</outer_angle>
                    <falloff>1</falloff>
                </spot>
                <direction>0 0 -1</direction>
                <cast_shadows>1</cast_shadows>
            </light>
            <sensor name="altimeter" type="altimeter">
                <always_on>1</always_on>
                <update_rate>5</update_rate>
                <topic>altimeter</topic>
            </sensor>
            <sensor name="imu_sensor" type="imu">
                <always_on>1</always_on>
                <update_rate>250</update_rate>
                <topic>imu</topic>
                <imu>
                    <enable_orientation>0</enable_orientation>
                    <angular_velocity>
                        <x>
                            <noise type="gaussian">
                                <mean>0</mean>
                                <stddev>0.009</stddev>
                                <bias_mean>0.00075</bias_mean>
                                <bias_stddev>0.005</bias_stddev>
                                <dynamic_bias_stddev>0.00002</dynamic_bias_stddev>
				<dynamic_bias_correlation_time>400.0</dynamic_bias_correlation_time>
				<precision>0.00025</precision>
                            </noise>
                        </x>
                        <y>
                            <noise type="gaussian">
                                <mean>0</mean>
                                <stddev>0.009</stddev>
                                <bias_mean>0.00075</bias_mean>
                                <bias_stddev>0.005</bias_stddev>
                                <dynamic_bias_stddev>0.00002</dynamic_bias_stddev>
				<dynamic_bias_correlation_time>400.0</dynamic_bias_correlation_time>
				<precision>0.00025</precision>
                            </noise>
                        </y>
                        <z>
                            <noise type="gaussian">
                                <mean>0</mean>
                                <stddev>0.009</stddev>
                                <bias_mean>0.00075</bias_mean>
                                <bias_stddev>0.005</bias_stddev>
                                <dynamic_bias_stddev>0.00002</dynamic_bias_stddev>
				<dynamic_bias_correlation_time>400.0</dynamic_bias_correlation_time>
				<precision>0.00025</precision>
                            </noise>
                        </z>
                    </angular_velocity>
                    <linear_acceleration>
                        <x>
                            <noise type="gaussian">
                                <mean>0</mean>
                                <stddev>0.021</stddev>
                                <bias_mean>0.05</bias_mean>
                                <bias_stddev>0.0075</bias_stddev>
                                <dynamic_bias_stddev>0.000375</dynamic_bias_stddev>
				<dynamic_bias_correlation_time>175.0</dynamic_bias_correlation_time>
				<precision>0.005</precision>
                            </noise>
                        </x>
                        <y>
                            <noise type="gaussian">
                                <mean>0</mean>
                                <stddev>0.021</stddev>
                                <bias_mean>0.05</bias_mean>
                                <bias_stddev>0.0075</bias_stddev>
                                <dynamic_bias_stddev>0.000375</dynamic_bias_stddev>
				<dynamic_bias_correlation_time>175.0</dynamic_bias_correlation_time>
				<precision>0.005</precision>
                            </noise>
                        </y>
                        <z>
                            <noise type="gaussian">
                                <mean>0</mean>
                                <stddev>0.021</stddev>
                                <bias_mean>0.05</bias_mean>
                                <bias_stddev>0.0075</bias_stddev>
                                <dynamic_bias_stddev>0.000375</dynamic_bias_stddev>
				<dynamic_bias_correlation_time>175.0</dynamic_bias_correlation_time>
				<precision>0.005</precision>
                            </noise>
                        </z>
                    </linear_acceleration>
                </imu>
            </sensor>
            <visual name="camera_visual">
                <pose>0.43 0 0.26 0 0 0</pose>
                <geometry>
                    <box>
                        <size>0.02 0.02 0.02</size>
                    </box>
                </geometry>
            </visual>
            <sensor name="camera" type="camera">
                <pose>0.43 0 0.26 0 0 0</pose>
                <camera>
                    <horizontal_fov>1.089</horizontal_fov>
                    <image>
                      <width>720</width>
                      <height>720</height>
                      <format>R8G8B8</format>
                    </image>
                    <clip>
                      <near>0.1</near>
                      <far>100</far>
                    </clip>
                </camera>
                <always_on>1</always_on>
                <update_rate>30</update_rate>
                <visualize>true</visualize>
                <topic>camera</topic>
            </sensor>
         
            <visual name="laser_visual">
                <pose>0.0 0 0.3 0 0 0</pose>
                <geometry>
                    <cylinder>
                        <radius>0.03</radius>
                        <length>0.1</length>
                    </cylinder>
                </geometry>
            </visual>
            <sensor name="front_laser" type="gpu_ray">
                <pose>0.0 0 0.394 0 0 0</pose>
                <update_rate>5</update_rate>
                <topic>lidar</topic>
                <lidar>
                    <scan>
                        <horizontal>
                            <samples>360</samples>
                            <resolution>1</resolution>
                            <min_angle>-3.14159</min_angle>
                            <max_angle>3.14159</max_angle>
                        </horizontal>
                        <vertical>
                            <samples>15</samples>
                            <resolution>1</resolution>
                            <min_angle>-0.3</min_angle>
                            <max_angle>0.3</max_angle>
                        </vertical>
                    </scan>
                    <range>
                        <min>0.05</min>
                        <max>10</max>
                        <resolution>0.01</resolution>
                    </range>
                    <noise>
                        <type>gaussian</type>
                        <mean>0</mean>
                        <stddev>0.005</stddev>
                    </noise>
                </lidar>
            </sensor>
        </link>
        <link name="front_left_wheel">
            <pose frame="">0.256 0.2854 0.03282 0 0 0</pose>
            <inertial>
                <mass>2.637</mass>
                <inertia>
                    <ixx>0.02467</ixx>
                    <ixy>0</ixy>
                    <ixz>0</ixz>
                    <iyy>0.04411</iyy>
                    <iyz>0</iyz>
                    <izz>0.02467</izz>
                </inertia>
            </inertial>
            <collision name="collision">
                <pose frame="">0 0 0 -1.5707963267948966 0 0</pose>
                <geometry>
                    <cylinder>
                        <length>0.1143</length>
                        <radius>0.1651</radius>
                    </cylinder>
                </geometry>
                <surface>
                    <friction>
                        <ode>
                            <mu>0.5</mu>
                            <mu2>1</mu2>
                            <slip1>0.00062</slip1>
                            <slip2>0</slip2>
                            <fdir1>0 0 1</fdir1>
                        </ode>
                    </friction>
                </surface>
            </collision>
            <visual name="visual">
                <geometry>
                    <mesh>
                        <uri>meshes/wheel.dae</uri>
                    </mesh>
                </geometry>
            </visual>
        </link>
        <joint name="front_left_wheel_joint" type="revolute">
            <parent>base_link</parent>
            <child>front_left_wheel</child>
            <axis>
                <xyz>0 1 0</xyz>
                <limit>
                    <lower>-1.79769e+308</lower>
                    <upper>+1.79769e+308</upper>
                </limit>
            </axis>
        </joint>
        <link name="front_right_wheel">
            <pose frame="">0.256 -0.2854 0.03282 0 0 0</pose>
            <inertial>
                <mass>2.637</mass>
                <inertia>
                    <ixx>0.02467</ixx>
                    <ixy>0</ixy>
                    <ixz>0</ixz>
                    <iyy>0.04411</iyy>
                    <iyz>0</iyz>
                    <izz>0.02467</izz>
                </inertia>
            </inertial>
            <collision name="collision">
                <pose frame="">0 0 0 -1.5707963267948966 0 0</pose>
                <geometry>
                    <cylinder>
                        <length>0.1143</length>
                        <radius>0.1651</radius>
                    </cylinder>
                </geometry>
                <surface>
                    <friction>
                        <ode>
                            <mu>0.5</mu>
                            <mu2>1</mu2>
                            <slip1>0.00062</slip1>
                            <slip2>0</slip2>
                            <fdir1>0 0 1</fdir1>
                        </ode>
                    </friction>
                </surface>
            </collision>
            <visual name="visual">
                <geometry>
                    <mesh>
                        <uri>meshes/wheel.dae</uri>
                    </mesh>
                </geometry>
            </visual>
        </link>
        <joint name="front_right_wheel_joint" type="revolute">
            <child>front_right_wheel</child>
            <parent>base_link</parent>
            <axis>
                <xyz>0 1 0</xyz>
                <limit>
                    <lower>-1.79769e+308</lower>
                    <upper>+1.79769e+308</upper>
                </limit>
            </axis>
        </joint>
        <link name="rear_left_wheel">
            <pose frame="">-0.256 0.2854 0.03282 0 0 0</pose>
            <inertial>
                <mass>2.637</mass>
                <inertia>
                    <ixx>0.02467</ixx>
                    <ixy>0</ixy>
                    <ixz>0</ixz>
                    <iyy>0.04411</iyy>
                    <iyz>0</iyz>
                    <izz>0.02467</izz>
                </inertia>
            </inertial>
            <collision name="collision">
                <pose frame="">0 0 0 -1.5707963267948966 0 0</pose>
                <geometry>
                    <cylinder>
                        <length>0.1143</length>
                        <radius>0.1651</radius>
                    </cylinder>
                </geometry>
                <surface>
                    <friction>
                        <ode>
                            <mu>0.5</mu>
                            <mu2>1</mu2>
                            <slip1>0.00062</slip1>
                            <slip2>0</slip2>
                            <fdir1>0 0 1</fdir1>
                        </ode>
                    </friction>
                </surface>
            </collision>
            <visual name="visual">
                <geometry>
                    <mesh>
                        <uri>meshes/wheel.dae</uri>
                    </mesh>
                </geometry>
            </visual>
        </link>
        <joint name="rear_left_wheel_joint" type="revolute">
            <parent>base_link</parent>
            <child>rear_left_wheel</child>
            <axis>
                <xyz>0 1 0</xyz>
                <limit>
                    <lower>-1.79769e+308</lower>
                    <upper>+1.79769e+308</upper>
                </limit>
            </axis>
        </joint>
        <link name="rear_right_wheel">
            <pose frame="">-0.256 -0.2854 0.03282 0 0 0</pose>
            <inertial>
                <mass>2.637</mass>
                <inertia>
                    <ixx>0.02467</ixx>
                    <ixy>0</ixy>
                    <ixz>0</ixz>
                    <iyy>0.04411</iyy>
                    <iyz>0</iyz>
                    <izz>0.02467</izz>
                </inertia>
            </inertial>
            <collision name="collision">
                <pose frame="">0 0 0 -1.5707963267948966 0 0</pose>
                <geometry>
                    <cylinder>
                        <length>0.1143</length>
                        <radius>0.1651</radius>
                    </cylinder>
                </geometry>
                <surface>
                    <friction>
                        <ode>
                            <mu>0.5</mu>
                            <mu2>1</mu2>
                            <slip1>0.00062</slip1>
                            <slip2>0</slip2>
                            <fdir1>0 0 1</fdir1>
                        </ode>
                    </friction>
                </surface>

            </collision>
            <visual name="visual">
                <geometry>
                    <mesh>
                        <uri>meshes/wheel.dae</uri>
                    </mesh>
                </geometry>
            </visual>
        </link>
        <joint name="rear_right_wheel_joint" type="revolute">
            <child>rear_right_wheel</child>
            <parent>base_link</parent>
            <axis>
                <xyz>0 1 0</xyz>
                <limit>
                    <lower>-1.79769e+308</lower>
                    <upper>+1.79769e+308</upper>
                </limit>
            </axis>
        </joint>
        <plugin filename="gz-sim-diff-drive-system"
            name="gz::sim::systems::DiffDrive">
            <left_joint>rear_left_wheel_joint</left_joint>
            <left_joint>front_left_wheel_joint</left_joint>
            <right_joint>rear_right_wheel_joint</right_joint>
            <right_joint>front_right_wheel_joint</right_joint>
            <wheel_separation>1.25</wheel_separation>
            <wheel_radius>0.3</wheel_radius>
            <odom_publish_frequency>1</odom_publish_frequency>  
            <topic>cmd_vel</topic>
	    </plugin>
    </model>
</sdf>
